Traceback (most recent call last):
  File "/usr/share/miniconda/envs/microdf/lib/python3.9/site-packages/jupyter_cache/executors/utils.py", line 58, in single_nb_execution
    executenb(
  File "/usr/share/miniconda/envs/microdf/lib/python3.9/site-packages/nbclient/client.py", line 1314, in execute
    return NotebookClient(nb=nb, resources=resources, km=km, **kwargs).execute()
  File "/usr/share/miniconda/envs/microdf/lib/python3.9/site-packages/jupyter_core/utils/__init__.py", line 165, in wrapped
    return loop.run_until_complete(inner)
  File "/usr/share/miniconda/envs/microdf/lib/python3.9/asyncio/base_events.py", line 647, in run_until_complete
    return future.result()
  File "/usr/share/miniconda/envs/microdf/lib/python3.9/site-packages/nbclient/client.py", line 709, in async_execute
    await self.async_execute_cell(
  File "/usr/share/miniconda/envs/microdf/lib/python3.9/site-packages/nbclient/client.py", line 1062, in async_execute_cell
    await self._check_raise_for_error(cell, cell_index, exec_reply)
  File "/usr/share/miniconda/envs/microdf/lib/python3.9/site-packages/nbclient/client.py", line 918, in _check_raise_for_error
    raise CellExecutionError.from_cell_and_msg(cell, exec_reply_content)
nbclient.exceptions.CellExecutionError: An error occurred while executing the following cell:
------------------
mdf.set_plot_style()
------------------


[0;31m---------------------------------------------------------------------------[0m
[0;31mAttributeError[0m                            Traceback (most recent call last)
Cell [0;32mIn[2], line 1[0m
[0;32m----> 1[0m [43mmdf[49m[38;5;241;43m.[39;49m[43mset_plot_style[49m[43m([49m[43m)[49m

File [0;32m~/work/microdf/microdf/microdf/style.py:29[0m, in [0;36mset_plot_style[0;34m(dpi)[0m
[1;32m     25[0m sns[38;5;241m.[39mset_style([38;5;124m"[39m[38;5;124mwhite[39m[38;5;124m"[39m)
[1;32m     27[0m [38;5;66;03m# Set up Roboto. Must be downloaded in the current directory.[39;00m
[1;32m     28[0m [38;5;66;03m# See https://stackoverflow.com/a/51844978/1840471.[39;00m
[0;32m---> 29[0m fm[38;5;241m.[39mfontManager[38;5;241m.[39mttflist [38;5;241m+[39m[38;5;241m=[39m [43mfm[49m[38;5;241;43m.[39;49m[43mcreateFontList[49m([[38;5;124m"[39m[38;5;124mRoboto-Regular.ttf[39m[38;5;124m"[39m])
[1;32m     31[0m STYLE [38;5;241m=[39m {
[1;32m     32[0m     [38;5;124m"[39m[38;5;124msavefig.dpi[39m[38;5;124m"[39m: dpi,
[1;32m     33[0m     [38;5;124m"[39m[38;5;124mfigure.dpi[39m[38;5;124m"[39m: dpi,
[0;32m   (...)[0m
[1;32m     51[0m     [38;5;124m"[39m[38;5;124maxes.spines.bottom[39m[38;5;124m"[39m: [38;5;28;01mFalse[39;00m,
[1;32m     52[0m }
[1;32m     54[0m mpl[38;5;241m.[39mrcParams[38;5;241m.[39mupdate(STYLE)

[0;31mAttributeError[0m: module 'matplotlib.font_manager' has no attribute 'createFontList'

